exception was thrown while monkey_patching for eventlet. to fix this error make sure you run eventlet.monkey_patch() before importing any other modules.
Traceback (most recent call last):
  File "/home/runner/workspace/.pythonlibs/lib/python3.11/site-packages/eventlet/patcher.py", line 611, in _upgrade_instances
    new = upgrade_or_traverse(v)
          ^^^^^^^^^^^^^^^^^^^^^^
  File "/home/runner/workspace/.pythonlibs/lib/python3.11/site-packages/eventlet/patcher.py", line 588, in upgrade_or_traverse
    _upgrade_instances(obj, klass, upgrade, visited, old_to_new)
  File "/home/runner/workspace/.pythonlibs/lib/python3.11/site-packages/eventlet/patcher.py", line 593, in _upgrade_instances
    new = upgrade_or_traverse(v)
          ^^^^^^^^^^^^^^^^^^^^^^
  File "/home/runner/workspace/.pythonlibs/lib/python3.11/site-packages/eventlet/patcher.py", line 588, in upgrade_or_traverse
    _upgrade_instances(obj, klass, upgrade, visited, old_to_new)
  File "/home/runner/workspace/.pythonlibs/lib/python3.11/site-packages/eventlet/patcher.py", line 602, in _upgrade_instances
    container_vars = vars(container)
                     ^^^^^^^^^^^^^^^
  File "/home/runner/workspace/.pythonlibs/lib/python3.11/site-packages/werkzeug/local.py", line 318, in __get__
    obj = instance._get_current_object()
          ^^^^^^^^^^^^^^^^^^^^^^^^^^^^^^
  File "/home/runner/workspace/.pythonlibs/lib/python3.11/site-packages/werkzeug/local.py", line 519, in _get_current_object
    raise RuntimeError(unbound_message) from None
RuntimeError: Working outside of request context.

This typically means that you attempted to use functionality that needed
an active HTTP request. Consult the documentation on testing for
information about how to avoid this problem.
An exception was thrown while monkey_patching for eventlet. to fix this error make sure you run eventlet.monkey_patch() before importing any other modules.
Traceback (most recent call last):
  File "/home/runner/workspace/.pythonlibs/lib/python3.11/site-packages/eventlet/patcher.py", line 611, in _upgrade_instances
    new = upgrade_or_traverse(v)
          ^^^^^^^^^^^^^^^^^^^^^^
  File "/home/runner/workspace/.pythonlibs/lib/python3.11/site-packages/eventlet/patcher.py", line 588, in upgrade_or_traverse
    _upgrade_instances(obj, klass, upgrade, visited, old_to_new)
  File "/home/runner/workspace/.pythonlibs/lib/python3.11/site-packages/eventlet/patcher.py", line 602, in _upgrade_instances
    container_vars = vars(container)
                     ^^^^^^^^^^^^^^^
  File "/home/runner/workspace/.pythonlibs/lib/python3.11/site-packages/werkzeug/local.py", line 318, in __get__
    obj = instance._get_current_object()
          ^^^^^^^^^^^^^^^^^^^^^^^^^^^^^^
  File "/home/runner/workspace/.pythonlibs/lib/python3.11/site-packages/werkzeug/local.py", line 519, in _get_current_object
    raise RuntimeError(unbound_message) from None
RuntimeError: Working outside of request context.

This typically means that you attempted to use functionality that needed
an active HTTP request. Consult the documentation on testing for
information about how to avoid this problem.
An exception was thrown while monkey_patching for eventlet. to fix this error make sure you run eventlet.monkey_patch() before importing any other modules.
Traceback (most recent call last):
  File "/home/runner/workspace/.pythonlibs/lib/python3.11/site-packages/eventlet/patcher.py", line 611, in _upgrade_instances
    new = upgrade_or_traverse(v)
          ^^^^^^^^^^^^^^^^^^^^^^
  File "/home/runner/workspace/.pythonlibs/lib/python3.11/site-packages/eventlet/patcher.py", line 588, in upgrade_or_traverse
    _upgrade_instances(obj, klass, upgrade, visited, old_to_new)
  File "/home/runner/workspace/.pythonlibs/lib/python3.11/site-packages/eventlet/patcher.py", line 602, in _upgrade_instances
    container_vars = vars(container)
                     ^^^^^^^^^^^^^^^
  File "/home/runner/workspace/.pythonlibs/lib/python3.11/site-packages/werkzeug/local.py", line 318, in __get__
    obj = instance._get_current_object()
          ^^^^^^^^^^^^^^^^^^^^^^^^^^^^^^
  File "/home/runner/workspace/.pythonlibs/lib/python3.11/site-packages/werkzeug/local.py", line 519, in _get_current_object
    raise RuntimeError(unbound_message) from None
RuntimeError: Working outside of application context.

This typically means that you attempted to use functionality that needed
the current application. To solve this, set up an application context
with app.app_context(). See the documentation for more information.
An exception was thrown while monkey_patching for eventlet. to fix this error make sure you run eventlet.monkey_patch() before importing any other modules.
Traceback (most recent call last):
  File "/home/runner/workspace/.pythonlibs/lib/python3.11/site-packages/eventlet/patcher.py", line 611, in _upgrade_instances
    new = upgrade_or_traverse(v)
          ^^^^^^^^^^^^^^^^^^^^^^
  File "/home/runner/workspace/.pythonlibs/lib/python3.11/site-packages/eventlet/patcher.py", line 588, in upgrade_or_traverse
    _upgrade_instances(obj, klass, upgrade, visited, old_to_new)
  File "/home/runner/workspace/.pythonlibs/lib/python3.11/site-packages/eventlet/patcher.py", line 602, in _upgrade_instances
    container_vars = vars(container)
                     ^^^^^^^^^^^^^^^
  File "/home/runner/workspace/.pythonlibs/lib/python3.11/site-packages/werkzeug/local.py", line 318, in __get__
    obj = instance._get_current_object()
          ^^^^^^^^^^^^^^^^^^^^^^^^^^^^^^
  File "/home/runner/workspace/.pythonlibs/lib/python3.11/site-packages/werkzeug/local.py", line 519, in _get_current_object
    raise RuntimeError(unbound_message) from None
RuntimeError: Working outside of application context.

This typically means that you attempted to use functionality that needed
the current application. To solve this, set up an application context
with app.app_context(). See the documentation for more information.
An exception was thrown while monkey_patching for eventlet. to fix this error make sure you run eventlet.monkey_patch() before importing any other modules.
Traceback (most recent call last):
  File "/home/runner/workspace/.pythonlibs/lib/python3.11/site-packages/eventlet/patcher.py", line 611, in _upgrade_instances
    new = upgrade_or_traverse(v)
          ^^^^^^^^^^^^^^^^^^^^^^
  File "/home/runner/workspace/.pythonlibs/lib/python3.11/site-packages/eventlet/patcher.py", line 588, in upgrade_or_traverse
    _upgrade_instances(obj, klass, upgrade, visited, old_to_new)
  File "/home/runner/workspace/.pythonlibs/lib/python3.11/site-packages/eventlet/patcher.py", line 602, in _upgrade_instances
    container_vars = vars(container)
                     ^^^^^^^^^^^^^^^
  File "/home/runner/workspace/.pythonlibs/lib/python3.11/site-packages/werkzeug/local.py", line 318, in __get__
    obj = instance._get_current_object()
          ^^^^^^^^^^^^^^^^^^^^^^^^^^^^^^
  File "/home/runner/workspace/.pythonlibs/lib/python3.11/site-packages/werkzeug/local.py", line 519, in _get_current_object
    raise RuntimeError(unbound_message) from None
RuntimeError: Working outside of request context.

This typically means that you attempted to use functionality that needed
an active HTTP request. Consult the documentation on testing for
information about how to avoid this problem.
An exception was thrown while monkey_patching for eventlet. to fix this error make sure you run eventlet.monkey_patch() before importing any other modules.
Traceback (most recent call last):
  File "/home/runner/workspace/.pythonlibs/lib/python3.11/site-packages/eventlet/patcher.py", line 611, in _upgrade_instances
    new = upgrade_or_traverse(v)
          ^^^^^^^^^^^^^^^^^^^^^^
  File "/home/runner/workspace/.pythonlibs/lib/python3.11/site-packages/eventlet/patcher.py", line 588, in upgrade_or_traverse
    _upgrade_instances(obj, klass, upgrade, visited, old_to_new)
  File "/home/runner/workspace/.pythonlibs/lib/python3.11/site-packages/eventlet/patcher.py", line 602, in _upgrade_instances
    container_vars = vars(container)
                     ^^^^^^^^^^^^^^^
  File "/home/runner/workspace/.pythonlibs/lib/python3.11/site-packages/werkzeug/local.py", line 318, in __get__
    obj = instance._get_current_object()
          ^^^^^^^^^^^^^^^^^^^^^^^^^^^^^^
  File "/home/runner/workspace/.pythonlibs/lib/python3.11/site-packages/werkzeug/local.py", line 519, in _get_current_object
    raise RuntimeError(unbound_message) from None
RuntimeError: Working outside of application context.

This typically means that you attempted to use functionality that needed
the current application. To solve this, set up an application context
with app.app_context(). See the documentation for more information.
2 RLock(s) were not greened, to fix this error make sure you run eventlet.monkey_patch() before importing any other modules.
ERROR:app:Exception on / [GET]
Traceback (most recent call last):
  File "/home/runner/workspace/.pythonlibs/lib/python3.11/site-packages/flask/app.py", line 1511, in wsgi_app
    response = self.full_dispatch_request()
               ^^^^^^^^^^^^^^^^^^^^^^^^^^^^
  File "/home/runner/workspace/.pythonlibs/lib/python3.11/site-packages/flask/app.py", line 919, in full_dispatch_request
    rv = self.handle_user_exception(e)
         ^^^^^^^^^^^^^^^^^^^^^^^^^^^^^
  File "/home/runner/workspace/.pythonlibs/lib/python3.11/site-packages/flask/app.py", line 917, in full_dispatch_request
    rv = self.dispatch_request()
         ^^^^^^^^^^^^^^^^^^^^^^^
  File "/home/runner/workspace/.pythonlibs/lib/python3.11/site-packages/flask/app.py", line 902, in dispatch_request
    return self.ensure_sync(self.view_functions[rule.endpoint])(**view_args)  # type: ignore[no-any-return]
           ^^^^^^^^^^^^^^^^^^^^^^^^^^^^^^^^^^^^^^^^^^^^^^^^^^^^^^^^^^^^^^^^^
  File "/home/runner/workspace/routes.py", line 25, in index
    featured_projects = Project.query.order_by(Project.created_at.desc()).limit(6).all()
                        ^^^^^^^^^^^^^^^^^^^^^^^^^^^^^^^^^^^^^^^^^^^^^^^^^^^^^^^^^^^^^^^^
  File "/home/runner/workspace/.pythonlibs/lib/python3.11/site-packages/sqlalchemy/orm/query.py", line 2704, in all
    return self._iter().all()  # type: ignore
           ^^^^^^^^^^^^
  File "/home/runner/workspace/.pythonlibs/lib/python3.11/site-packages/sqlalchemy/orm/query.py", line 2858, in _iter
    result: Union[ScalarResult[_T], Result[_T]] = self.session.execute(
                                                  ^^^^^^^^^^^^^^^^^^^^^
  File "/home/runner/workspace/.pythonlibs/lib/python3.11/site-packages/sqlalchemy/orm/session.py", line 2365, in execute
    return self._execute_internal(
           ^^^^^^^^^^^^^^^^^^^^^^^
  File "/home/runner/workspace/.pythonlibs/lib/python3.11/site-packages/sqlalchemy/orm/session.py", line 2241, in _execute_internal
    conn = self._connection_for_bind(bind)
           ^^^^^^^^^^^^^^^^^^^^^^^^^^^^^^^
  File "/home/runner/workspace/.pythonlibs/lib/python3.11/site-packages/sqlalchemy/orm/session.py", line 2110, in _connection_for_bind
    return trans._connection_for_bind(engine, execution_options)
           ^^^^^^^^^^^^^^^^^^^^^^^^^^^^^^^^^^^^^^^^^^^^^^^^^^^^^
  File "<string>", line 2, in _connection_for_bind
  File "/home/runner/workspace/.pythonlibs/lib/python3.11/site-packages/sqlalchemy/orm/state_changes.py", line 139, in _go
    ret_value = fn(self, *arg, **kw)
                ^^^^^^^^^^^^^^^^^^^^
  File "/home/runner/workspace/.pythonlibs/lib/python3.11/site-packages/sqlalchemy/orm/session.py", line 1189, in _connection_for_bind
    conn = bind.connect()
           ^^^^^^^^^^^^^^
  File "/home/runner/workspace/.pythonlibs/lib/python3.11/site-packages/sqlalchemy/engine/base.py", line 3274, in connect
    return self._connection_cls(self)
           ^^^^^^^^^^^^^^^^^^^^^^^^^^
  File "/home/runner/workspace/.pythonlibs/lib/python3.11/site-packages/sqlalchemy/engine/base.py", line 146, in __init__
    self._dbapi_connection = engine.raw_connection()
                             ^^^^^^^^^^^^^^^^^^^^^^^
  File "/home/runner/workspace/.pythonlibs/lib/python3.11/site-packages/sqlalchemy/engine/base.py", line 3298, in raw_connection
    return self.pool.connect()
           ^^^^^^^^^^^^^^^^^^^
  File "/home/runner/workspace/.pythonlibs/lib/python3.11/site-packages/sqlalchemy/pool/base.py", line 449, in connect
    return _ConnectionFairy._checkout(self)
           ^^^^^^^^^^^^^^^^^^^^^^^^^^^^^^^^
  File "/home/runner/workspace/.pythonlibs/lib/python3.11/site-packages/sqlalchemy/pool/base.py", line 1264, in _checkout
    fairy = _ConnectionRecord.checkout(pool)
            ^^^^^^^^^^^^^^^^^^^^^^^^^^^^^^^^
  File "/home/runner/workspace/.pythonlibs/lib/python3.11/site-packages/sqlalchemy/pool/base.py", line 713, in checkout
    rec = pool._do_get()
          ^^^^^^^^^^^^^^
  File "/home/runner/workspace/.pythonlibs/lib/python3.11/site-packages/sqlalchemy/pool/impl.py", line 158, in _do_get
    return self._pool.get(wait, self._timeout)
           ^^^^^^^^^^^^^^^^^^^^^^^^^^^^^^^^^^^
  File "/home/runner/workspace/.pythonlibs/lib/python3.11/site-packages/sqlalchemy/util/queue.py", line 203, in get
    self.not_full.notify()
  File "/nix/store/clx0mcir7qw8zk36zbr4jra789g3knf6-python3-3.11.10/lib/python3.11/threading.py", line 377, in notify
    raise RuntimeError("cannot notify on un-acquired lock")
RuntimeError: cannot notify on un-acquired lock
[2025-05-15 21:02:18 +0000] [3069] [INFO] Worker reloading: /home/runner/workspace/main.py modified
[2025-05-15 21:02:18 +0000] [3069] [INFO] Worker exiting (pid: 3069)
[2025-05-15 21:02:19 +0000] [3121] [INFO] Booting worker with pid: 3121
INFO:app:Using database URL: postgresql://neondb_owner:npg_gwmfT2cOaS5B@ep-patient-haze-a5w3pei6.us-east-2.aws.neon.tech/neondb?sslmode=require
INFO:app:Initializing Flask application with configurations
INFO:main:Database tables created
[2025-05-15 21:02:26 +0000] [3121] [INFO] Worker reloading: /home/runner/workspace/app.py modified
[2025-05-15 21:02:26 +0000] [3121] [INFO] Worker exiting (pid: 3121)
[2025-05-15 21:02:26 +0000] [3171] [INFO] Booting worker with pid: 3171
INFO:app:Using database URL: postgresql://neondb_owner:npg_gwmfT2cOaS5B@ep-patient-haze-a5w3pei6.us-east-2.aws.neon.tech/neondb?sslmode=require
INFO:app:Initializing Flask application with configurations
INFO:main:Database tables created
DEBUG:routes:User stux joined room user_2
[2025-05-15 21:03:05 +0000] [3171] [ERROR] Error handling request /socket.io/?EIO=4&transport=polling&t=PRLmSr6&sid=yfZVPCD609FonUs2AAAA
Traceback (most recent call last):
  File "/home/runner/workspace/.pythonlibs/lib/python3.11/site-packages/gunicorn/workers/sync.py", line 134, in handle
    self.handle_request(listener, req, client, addr)
  File "/home/runner/workspace/.pythonlibs/lib/python3.11/site-packages/gunicorn/workers/sync.py", line 177, in handle_request
    respiter = self.wsgi(environ, resp.start_response)
               ^^^^^^^^^^^^^^^^^^^^^^^^^^^^^^^^^^^^^^^
  File "/home/runner/workspace/.pythonlibs/lib/python3.11/site-packages/flask/app.py", line 1536, in __call__
    return self.wsgi_app(environ, start_response)
           ^^^^^^^^^^^^^^^^^^^^^^^^^^^^^^^^^^^^^^
  File "/home/runner/workspace/.pythonlibs/lib/python3.11/site-packages/flask_socketio/__init__.py", line 42, in __call__
    return super().__call__(environ, start_response)
           ^^^^^^^^^^^^^^^^^^^^^^^^^^^^^^^^^^^^^^^^^
  File "/home/runner/workspace/.pythonlibs/lib/python3.11/site-packages/engineio/middleware.py", line 63, in __call__
    return self.engineio_app.handle_request(environ, start_response)
           ^^^^^^^^^^^^^^^^^^^^^^^^^^^^^^^^^^^^^^^^^^^^^^^^^^^^^^^^^
  File "/home/runner/workspace/.pythonlibs/lib/python3.11/site-packages/socketio/server.py", line 434, in handle_request
    return self.eio.handle_request(environ, start_response)
           ^^^^^^^^^^^^^^^^^^^^^^^^^^^^^^^^^^^^^^^^^^^^^^^^
  File "/home/runner/workspace/.pythonlibs/lib/python3.11/site-packages/engineio/server.py", line 305, in handle_request
    socket = self._get_socket(sid)
             ^^^^^^^^^^^^^^^^^^^^^
  File "/home/runner/workspace/.pythonlibs/lib/python3.11/site-packages/engineio/base_server.py", line 242, in _get_socket
    raise KeyError('Session is disconnected')
KeyError: 'Session is disconnected'
Invalid session yfZVPCD609FonUs2AAAA (further occurrences of this error will be logged with level INFO)
ERROR:engineio.server:Invalid session yfZVPCD609FonUs2AAAA (further occurrences of this error will be logged with level INFO)